<robot name="miura_bot">

  <!-- Materials -->
  <material name="blue">
    <color rgba = "0 0 0.8 1"/>
  </material>
  <material name="red">
    <color rgba = "0.8 0.0 0 1"/>
  </material>
  <material name="green">
    <color rgba = "0.0 0.8 0 1"/>
  </material>
  <material name="purple">
    <color rgba = "0.4 0.1 0.8 1"/>
  </material>

  <!-- base_link -->
  <link name="base_link">
    <visual>
      <origin rpy="0.0 0 0" xyz="0 0 0"/>
      <geometry>
        <mesh filename="mori-design-2.stl" scale="1.00 1.00 1.00"/>
      </geometry>
    </visual>
    <collision>
      <origin rpy="0.0 0 0" xyz="0 0 0"/>
      <geometry>
        <mesh filename="mori-design-2.stl" scale="1.00 1.00 1.00"/>
      </geometry>
    </collision>
  </link>

  <!-- wheel1 -->
  <link name="wheel1">
    <visual>
      <origin rpy="0.0 0 0" xyz="-8 0 -8"/>
      <geometry>
        <mesh filename="wheel.stl" scale="1.00 1.00 1.00"/>
      </geometry>
      <material name="blue"/>
    </visual>
    <collision>
      <origin rpy="0.0 0 0" xyz="-8 0 -8"/>
      <geometry>
        <mesh filename="wheel.stl" scale="1.00 1.00 1.00"/>
      </geometry>
    </collision>
  </link>

  <joint name="joint1" type="continuous">
    <parent link="base_link"/>
    <child link="wheel1"/>
    <axis xyz="0 1 0"/>
    <origin rpy="0 0 0" xyz="5 103 8"/>
  </joint>

  <!-- wheel2 -->
  <link name="wheel2">
    <visual>
      <origin rpy="0.0 0 0" xyz="-8 0 -8"/>
      <geometry>
        <mesh filename="wheel.stl" scale="1.00 1.00 1.00"/>
      </geometry>
      <material name="blue"/>
    </visual>
    <collision>
      <origin rpy="0.0 0 0" xyz="-8 0 -8"/>
      <geometry>
        <mesh filename="wheel.stl" scale="1.00 1.00 1.00"/>
      </geometry>
    </collision>
  </link>

  <joint name="joint2" type="continuous">
    <parent link="base_link"/>
    <child link="wheel2"/>
    <axis xyz="0 1 0"/>
    <origin rpy="0 0 0" xyz="135 118 8"/>
  </joint>

  <!-- wheel3 -->
  <link name="wheel3">
    <visual>
      <origin rpy="0.0 0 0" xyz="-8 0 -8"/>
      <geometry>
        <mesh filename="wheel.stl" scale="1.00 1.00 1.00"/>
      </geometry>
      <material name="blue"/>
    </visual>
    <collision>
      <origin rpy="0.0 0 0" xyz="-8 0 -8"/>
      <geometry>
        <mesh filename="wheel.stl" scale="1.00 1.00 1.00"/>
      </geometry>
    </collision>
  </link>

  <joint name="joint3" type="continuous">
    <parent link="base_link"/>
    <child link="wheel3"/>
    <axis xyz="0 1 0"/>
    <origin rpy="0 0 2.0944" xyz="46 25 8"/>
  </joint>

  <!-- wheel4 -->
  <link name="wheel4">
    <visual>
      <origin rpy="0.0 0 0" xyz="-8 0 -8"/>
      <geometry>
        <mesh filename="wheel.stl" scale="1.00 1.00 1.00"/>
      </geometry>
      <material name="blue"/>
    </visual>
    <collision>
      <origin rpy="0.0 0 0" xyz="-8 0 -8"/>
      <geometry>
        <mesh filename="wheel.stl" scale="1.00 1.00 1.00"/>
      </geometry>
    </collision>
  </link>

  <joint name="joint4" type="continuous">
    <parent link="base_link"/>
    <child link="wheel4"/>
    <axis xyz="0 1 0"/>
    <origin rpy="0 0 2.0944" xyz="99 202 8"/>
  </joint>

  <!-- motor1 -->
  <link name="motor1">
    <visual>
      <origin rpy="0.0 0 0" xyz="0 -6 -5"/>
      <geometry>
        <mesh filename="motor.stl" scale="1.00 1.00 1.00"/>
      </geometry>
      <material name="green"/>
    </visual>
    <collision>
      <origin rpy="0 0 0" xyz="0 -6 -5"/>
      <geometry>
        <mesh filename="motor.stl" scale="1.00 1.00 1.00"/>
      </geometry>
    </collision>
    <inertial>
      <origin xyz="13.6 0 0" rpy="0 0 0.0"/>
      <mass value="0.330"/>
      <inertia ixx="6.710" ixy="0.0" ixz="0.0" 
      iyy="24.3067968176" iyz="0.0" izz="23.0967968176"/>
    </inertial>>
  </link>

  <joint name="jointmotor1" type="fixed">
    <parent link="base_link"/>
    <child link="motor1"/>
    <origin rpy="0 0 4.71238898038" xyz="28.0000052838 115 5"/> 
  </joint>

  <!-- motor2 -->
  <link name="motor2">
    <visual>
      <origin rpy="0.0 0 0" xyz="0 -6 -5"/>
      <geometry>
        <mesh filename="motor_tip.stl" scale="1.00 1.00 1.00"/>
      </geometry>
      <material name="green"/>
    </visual>
    <collision>
      <origin rpy="0 0 0" xyz="0 -6 -5"/>
      <geometry>
        <mesh filename="motor_tip.stl" scale="1.00 1.00 1.00"/>
      </geometry>
    </collision>
    <inertial>
      <origin xyz="13.6 0 0" rpy="0 0 0.0"/>
      <mass value="0"/>
      <inertia ixx="0" ixy="0.0" ixz="0.0" 
      iyy="0" iyz="0.0" izz="0"/>
    </inertial>
  </link>

  <joint name="jointmotor2" type="fixed">
    <parent link="base_link"/>
    <child link="motor2"/>
    <origin rpy="0 0 1.57079632679" xyz="113.9 110 5"/> 
  </joint>

  <!-- motor3 -->
  <link name="motor3">
    <visual>
      <origin rpy="0.0 0 0" xyz="0 -6 -5"/>
      <geometry>
        <mesh filename="motor.stl" scale="1.00 1.00 1.00"/>
      </geometry>
      <material name="green"/>
    </visual>
    <collision>
      <origin rpy="0 0 0" xyz="0 -6 -5"/>
      <geometry>
        <mesh filename="motor.stl" scale="1.00 1.00 1.00"/>
      </geometry>
    </collision>
    <inertial>
      <origin xyz="13.6 0 0" rpy="0 0 0.0"/>
      <mass value="0"/>
      <inertia ixx="0" ixy="0.0" ixz="0.0" 
      iyy="0" iyz="0.0" izz="0"/>
    </inertial>
  </link>

  <joint name="jointmotor3" type="fixed">
    <parent link="base_link"/>
    <child link="motor3"/>
    <origin rpy="0 0 0.523598775598" xyz="25.31 36.5526 5"/> 
  </joint>

  <!-- motor4 -->
  <link name="motor4">
    <visual>
      <origin rpy="0.0 0 0" xyz="0 -6 -5"/>
      <geometry>
        <mesh filename="motor.stl" scale="1.00 1.00 1.00"/>
      </geometry>
      <material name="green"/>
    </visual>
    <collision>
      <origin rpy="0 0 0" xyz="0 -6 -5"/>
      <geometry>
        <mesh filename="motor.stl" scale="1.00 1.00 1.00"/>
      </geometry>
    </collision>
    <inertial>
      <origin xyz="13.6 0 0" rpy="0 0 0.0"/>
      <mass value="0"/>
      <inertia ixx="0" ixy="0.0" ixz="0.0" 
      iyy="0" iyz="0.0" izz="0"/>
    </inertial>
  </link>

  <joint name="jointmotor4" type="fixed">
    <parent link="base_link"/>
    <child link="motor4"/>
    <origin rpy="0 0 3.66519142919" xyz="116.593 188.447 5"/> 
  </joint>

</robot>