<robot name="miura-ori_pattern">

  <!-- Materials -->
  <material name="blue">
    <color rgba = "0 0 0.8 1"/>
  </material>
  <material name="red">
    <color rgba = "0.8 0 0 1"/>
  </material>

  <link name="base_link_a">
    <visual>
      <origin rpy="0.0 0 0.0" xyz="-5.9493 0.0 -6.0"/>
      <geometry>
        <mesh filename="mori-design-2.stl" scale="1.00 1.00 1.00"/>
      </geometry>
    </visual>
    <collision>
      <origin rpy="0.0 0 0.0" xyz="-5.9493 0.0 -6.0"/>
      <geometry>
        <mesh filename="mori-design-2.stl" scale="1.00 1.00 1.00"/>
      </geometry>
    </collision>
    <inertial>
      <origin xyz="64.9519 112.5 0.0" rpy="0 0 0.0"/>
      <mass value="0.100"/>
      <inertia ixx="6.25e-05" ixy="0.0" ixz="0.0" iyy="0.00025" iyz="0.0" izz="0.00019"/>
    </inertial>
  </link>

  <link name="base_link_b">
    <visual>
      <origin rpy="0.0 0 1.0472" xyz="-2.97465 -2.97465 -6.0"/>
      <geometry>
        <mesh filename="mori-design-2.stl" scale="1.00 1.00 1.00"/>
      </geometry>
    </visual>
    <collision>
      <origin rpy="0.0 0 1.0472" xyz="-2.97465 -2.97465 -6.0"/>
      <geometry>
        <mesh filename="mori-design-2.stl" scale="1.00 1.00 1.00"/>
      </geometry>
    </collision>
    <inertial>
      <origin xyz="-64.9519 129.9038 0.0" rpy="0 0 0.0"/>
      <mass value="0.100"/>
      <inertia ixx="6.25e-05" ixy="0.0" ixz="0.0" iyy="0.00025" iyz="0.0" izz="0.00019"/>
    </inertial>
  </link>

  <joint name="shaft_a_b" type="revolute">
    <parent link="base_link_a"/>
    <child link="base_link_b"/>
    <axis xyz="0 1 0"/>
    <origin rpy="0 0 0" xyz="0.0 -2.0 0.0"/>
    <limit effort="40" lower="-3.14" upper="3.14" velocity="0.1"/>
  </joint>

  <link name="wheel_1_a">
    <visual>
      <origin rpy="0.0 0 0" xyz="-8.0 -2.0 -8.0"/>
      <geometry>
        <mesh filename="wheel.stl" scale="1.00 1.00 1.00"/>
      </geometry>
      <material name="blue"/>
    </visual>
    <collision>
      <origin rpy="0.0 0 0" xyz="-8.0 -2.0 -8.0"/>
      <geometry>
        <mesh filename="wheel.stl" scale="1.00 1.00 1.00"/>
      </geometry>
    </collision>
  </link>

  <joint name="shaft_1_a" type="continuous">
    <parent link="base_link_a"/>
    <child link="wheel_1_a"/>
    <axis xyz="0 1 0"/>
    <origin rpy="0 0 0" xyz="0.0 105.0 0"/>
  </joint>

  <link name="wheel_2_a">
    <visual>
      <origin rpy="0.0 0.0 0.0" xyz="-8.0 -2.0 -8.0"/>
      <geometry>
        <mesh filename="wheel.stl" scale="1.00 1.00 1.00"/>
      </geometry>
      <material name="blue"/>
    </visual>
    <collision>
      <origin rpy="0.0 0.0 0.0" xyz="-8.0 -2.0 -8.0"/>
      <geometry>
        <mesh filename="wheel.stl" scale="1.00 1.00 1.00"/>
      </geometry>
    </collision>
  </link>

  <joint name="shaft_2_a" type="continuous">
    <parent link="base_link_a"/>
    <child link="wheel_2_a"/>
    <axis xyz="0 1 0"/>
    <origin rpy="0 0 -1.0472" xyz="38.9711 22.5 0"/>
  </joint>

  <link name="wheel_3_a">
    <visual>
      <origin rpy="0.0 0.0 0.0" xyz="-8.0 -2.0 -8.0"/>
      <geometry>
        <mesh filename="wheel.stl" scale="1.00 1.00 1.00"/>
      </geometry>
      <material name="blue"/>
    </visual>
    <collision>
      <origin rpy="0.0 0.0 0.0" xyz="-8.0 -2.0 -8.0"/>
      <geometry>
        <mesh filename="wheel.stl" scale="1.00 1.00 1.00"/>
      </geometry>
    </collision>
  </link>

  <joint name="shaft_3_a" type="continuous">
    <parent link="base_link_a"/>
    <child link="wheel_3_a"/>
    <axis xyz="0 1 0"/>
    <origin rpy="0 0 0" xyz="129.9038 120.0 0"/>
  </joint>

  <link name="wheel_4_a">
    <visual>
      <origin rpy="0.0 0.0 0.0" xyz="-8.0 -2.0 -8.0"/>
      <geometry>
        <mesh filename="wheel.stl" scale="1.00 1.00 1.00"/>
      </geometry>
      <material name="blue"/>
    </visual>
    <collision>
      <origin rpy="0.0 0.0 0.0" xyz="-8.0 -2.0 -8.0"/>
      <geometry>
        <mesh filename="wheel.stl" scale="1.00 1.00 1.00"/>
      </geometry>
    </collision>
  </link>

  <joint name="shaft_4_a" type="continuous">
    <parent link="base_link_a"/>
    <child link="wheel_4_a"/>
    <axis xyz="0 1 0"/>
    <origin rpy="0 0 -1.0472" xyz="90.9327 202.5 0"/>
  </joint>

  <link name="wheel_1_b">
    <visual>
      <origin rpy="0.0 0 0.0" xyz="-8.0 -2.0 -8.0"/>
      <geometry>
        <mesh filename="wheel.stl" scale="1.00 1.00 1.00"/>
      </geometry>
      <material name="blue"/>
    </visual>
    <collision>
      <origin rpy="0.0 0 0" xyz="-8.0 -2.0 -8.0"/>
      <geometry>
        <mesh filename="wheel.stl" scale="1.00 1.00 1.00"/>
      </geometry>
    </collision>
  </link>

  <joint name="shaft_1_b" type="continuous">
    <parent link="base_link_b"/>
    <child link="wheel_1_b"/>
    <axis xyz="0 1 0"/>
    <origin rpy="0 0 1.0472" xyz="-90.9326674 54.5 0"/>
  </joint>

  <link name="wheel_2_b">
    <visual>
      <origin rpy="0.0 0.0 0.0" xyz="-8.0 -2.0 -8.0"/>
      <geometry>
        <mesh filename="wheel.stl" scale="1.00 1.00 1.00"/>
      </geometry>
      <material name="blue"/>
    </visual>
    <collision>
      <origin rpy="0.0 0.0 0.0" xyz="-8.0 -2.0 -8.0"/>
      <geometry>
        <mesh filename="wheel.stl" scale="1.00 1.00 1.00"/>
      </geometry>
    </collision>
  </link>

  <joint name="shaft_2_b" type="continuous">
    <parent link="base_link_b"/>
    <child link="wheel_2_b"/>
    <axis xyz="0 1 0"/>
    <origin rpy="0 0 0.0" xyz="0.0 47.0 0"/>
  </joint>

  <link name="wheel_3_b">
    <visual>
      <origin rpy="0.0 0.0 0.0" xyz="-8.0 -2.0 -8.0"/>
      <geometry>
        <mesh filename="wheel.stl" scale="1.00 1.00 1.00"/>
      </geometry>
      <material name="blue"/>
    </visual>
    <collision>
      <origin rpy="0.0 0.0 0.0" xyz="-8.0 -2.0 -8.0"/>
      <geometry>
        <mesh filename="wheel.stl" scale="1.00 1.00 1.00"/>
      </geometry>
    </collision>
  </link>

  <joint name="shaft_3_b" type="continuous">
    <parent link="base_link_b"/>
    <child link="wheel_3_b"/>
    <axis xyz="0 1 0"/>
    <origin rpy="0 0 1.0472" xyz="-38.9711 174.5 0"/>
  </joint>

  <link name="wheel_4_b">
    <visual>
      <origin rpy="0.0 0.0 0.0" xyz="-8.0 -2.0 -8.0"/>
      <geometry>
        <mesh filename="wheel.stl" scale="1.00 1.00 1.00"/>
      </geometry>
      <material name="blue"/>
    </visual>
    <collision>
      <origin rpy="0.0 0.0 0.0" xyz="-8.0 -2.0 -8.0"/>
      <geometry>
        <mesh filename="wheel.stl" scale="1.00 1.00 1.00"/>
      </geometry>
    </collision>
  </link>

  <joint name="shaft_4_b" type="continuous">
    <parent link="base_link_b"/>
    <child link="wheel_4_b"/>
    <axis xyz="0 1 0"/>
    <origin rpy="0 0 0.0" xyz="-129.9038 182.0 0"/>
  </joint>

</robot>