<robot name="miura_bot">

  <!-- Materials -->
  <material name="blue">
    <color rgba = "0 0 0.8 1"/>
  </material>

  <!-- Links -->
  <link name="base_link">
    <visual>
      <origin rpy="0.0 0 0" xyz="0 0 0"/>
      <geometry>
        <mesh filename="mori-design-2.stl" scale="1.00 1.00 1.00"/>
      </geometry>
    </visual>
    <collision>
      <origin rpy="0.0 0 0" xyz="0 0 0"/>
      <geometry>
        <mesh filename="mori-design-2.stl" scale="1.00 1.00 1.00"/>
      </geometry>
    </collision>
  </link>

  <link name="wheel1">
    <visual>
      <origin rpy="0.0 0 0" xyz="0 0 0"/>
      <geometry>
        <mesh filename="wheel.stl" scale="1.00 1.00 1.00"/>
      </geometry>
      <material name="blue"/>
    </visual>
    <collision>
      <origin rpy="0.0 0 0" xyz="0 0 0"/>
      <geometry>
        <mesh filename="wheel.stl" scale="1.00 1.00 1.00"/>
      </geometry>
    </collision>
  </link>

  <link name="wheel2">
    <visual>
      <origin rpy="0.0 0 0" xyz="0 0 0"/>
      <geometry>
        <mesh filename="wheel.stl" scale="1.00 1.00 1.00"/>
      </geometry>
      <material name="blue"/>
    </visual>
    <collision>
      <origin rpy="0.0 0 0" xyz="0 0 0"/>
      <geometry>
        <mesh filename="wheel.stl" scale="1.00 1.00 1.00"/>
      </geometry>
    </collision>
  </link>

  <link name="wheel3">
    <visual>
      <origin rpy="0.0 0 0" xyz="0 0 0"/>
      <geometry>
        <mesh filename="wheel.stl" scale="1.00 1.00 1.00"/>
      </geometry>
      <material name="blue"/>
    </visual>
    <collision>
      <origin rpy="0.0 0 0" xyz="0 0 0"/>
      <geometry>
        <mesh filename="wheel.stl" scale="1.00 1.00 1.00"/>
      </geometry>
    </collision>
  </link>

  <link name="wheel4">
    <visual>
      <origin rpy="0.0 0 0" xyz="0 0 0"/>
      <geometry>
        <mesh filename="wheel.stl" scale="1.00 1.00 1.00"/>
      </geometry>
      <material name="blue"/>
    </visual>
    <collision>
      <origin rpy="0.0 0 0" xyz="0 0 0"/>
      <geometry>
        <mesh filename="wheel.stl" scale="1.00 1.00 1.00"/>
      </geometry>
    </collision>
  </link>

  <!-- Joints -->
  <joint name="joint1" type="continuous">
    <parent link="base_link"/>
    <child link="wheel1"/>
    <axis xyz="0 1 0"/>
    <!-- <limit effort="1000.0" lower="-1.571" upper="1.571" velocity="0.5"/> -->
    <origin rpy="0 0 0" xyz="0 103 0"/>
  </joint>
    
  <joint name="joint2" type="continuous">
    <parent link="base_link"/>
    <child link="wheel2"/>
    <axis xyz="0 1 0"/>
    <!-- <limit effort="1000.0" lower="-1.571" upper="1.571" velocity="0.5"/> -->
    <origin rpy="0 0 0" xyz="130 118 0"/>
  </joint>

  <joint name="joint3" type="continuous">
    <parent link="base_link"/>
    <child link="wheel3"/>
    <axis xyz="0 1 0"/>
    <!-- <limit effort="1000.0" lower="-1.571" upper="1.571" velocity="0.5"/> -->
    <origin rpy="0 0 2.0944" xyz="52 17 0"/>
  </joint>

  <joint name="joint4" type="continuous">
    <parent link="base_link"/>
    <child link="wheel4"/>
    <axis xyz="0 1 0"/>
    <!-- <limit effort="1000.0" lower="-1.571" upper="1.571" velocity="0.5"/> -->
    <origin rpy="0 0 2.0944" xyz="105 196 0"/>
  </joint>

</robot>