<robot name="miura-ori_pattern">

  <!-- Materials -->
  <material name="blue">
    <color rgba = "0 0 0.8 1"/>
  </material>

  <!-- base_link -->
  <link name="base_link">
    <visual>
      <origin rpy="0.0 0 0" xyz="0 0 0"/>
      <geometry>
        <mesh filename="mori-design-2.stl" scale="1.00 1.00 1.00"/>
      </geometry>
    </visual>
    <collision>
      <origin rpy="0.0 0 0" xyz="0 0 0"/>
      <geometry>
        <mesh filename="mori-design-2.stl" scale="1.00 1.00 1.00"/>
      </geometry>
    </collision>
    <inertial>
      <mass value="0.100"/>
      <inertia ixx="6.25e-05" ixy="0.0" ixz="0.0" iyy="0.00025" iyz="0.0" izz="0.00019"/> <!--w=0.15, d=0.086, h=0.01, m=0.1-->
    </inertial>
  </link>

  <!-- wheel1 -->
  <link name="wheel1">
    <visual>
      <origin rpy="0.0 0 0" xyz="-8 0 -8"/>
      <geometry>
        <mesh filename="wheel.stl" scale="1.00 1.00 1.00"/>
      </geometry>
      <material name="blue"/>
    </visual>
    <collision>
      <origin rpy="0.0 0 0" xyz="-8 0 -8"/>
      <geometry>
        <mesh filename="wheel.stl" scale="1.00 1.00 1.00"/>
      </geometry>
    </collision>
  </link>

  <joint name="joint1" type="revolute">
    <parent link="base_link"/>
    <child link="wheel1"/>
    <axis xyz="0 1 0"/>
    <origin rpy="0 0 0" xyz="5 103 8"/>
    <limit effort="40" lower="-3.14" upper="3.14" velocity="0.1"/>
  </joint>

  <!-- wheel2 -->
  <link name="wheel2">
    <visual>
      <origin rpy="0.0 0 0" xyz="-8 0 -8"/>
      <geometry>
        <mesh filename="wheel.stl" scale="1.00 1.00 1.00"/>
      </geometry>
      <material name="blue"/>
    </visual>
    <collision>
      <origin rpy="0.0 0 0" xyz="-8 0 -8"/>
      <geometry>
        <mesh filename="wheel.stl" scale="1.00 1.00 1.00"/>
      </geometry>
    </collision>
  </link>

  <joint name="joint2" type="revolute">
    <parent link="base_link"/>
    <child link="wheel2"/>
    <axis xyz="0 1 0"/>
    <origin rpy="0 0 0" xyz="135 118 8"/>
    <limit effort="40" lower="-3.14" upper="3.14" velocity="0.1"/>
  </joint>

  <!-- wheel3 -->
  <link name="wheel3">
    <visual>
      <origin rpy="0.0 0 0" xyz="-8 0 -8"/>
      <geometry>
        <mesh filename="wheel.stl" scale="1.00 1.00 1.00"/>
      </geometry>
      <material name="blue"/>
    </visual>
    <collision>
      <origin rpy="0.0 0 0" xyz="-8 0 -8"/>
      <geometry>
        <mesh filename="wheel.stl" scale="1.00 1.00 1.00"/>
      </geometry>
    </collision>
  </link>

  <joint name="joint3" type="revolute">
    <parent link="base_link"/>
    <child link="wheel3"/>
    <axis xyz="0 1 0"/>
    <origin rpy="0 0 2.0944" xyz="46 25 8"/>
    <limit effort="40" lower="-3.14" upper="3.14" velocity="0.1"/>
  </joint>

  <!-- wheel4 -->
  <link name="wheel4">
    <visual>
      <origin rpy="0.0 0 0" xyz="-8 0 -8"/>
      <geometry>
        <mesh filename="wheel.stl" scale="1.00 1.00 1.00"/>
      </geometry>
      <material name="blue"/>
    </visual>
    <collision>
      <origin rpy="0.0 0 0" xyz="-8 0 -8"/>
      <geometry>
        <mesh filename="wheel.stl" scale="1.00 1.00 1.00"/>
      </geometry>
    </collision>
  </link>

  <joint name="joint4" type="revolute">
    <parent link="base_link"/>
    <child link="wheel4"/>
    <axis xyz="0 1 0"/>
    <origin rpy="0 0 2.0944" xyz="99 202 8"/>
    <limit effort="40" lower="-3.14" upper="3.14" velocity="0.1"/>
  </joint>

  <!-- base_link -->
  <link name="base_link_b">
    <visual>
      <origin rpy="0.0 0 0" xyz="0 0 0"/>
      <geometry>
        <mesh filename="mori-design-2.stl" scale="1.00 1.00 1.00"/>
      </geometry>
    </visual>
    <collision>
      <origin rpy="0.0 0 0" xyz="0 0 0"/>
      <geometry>
        <mesh filename="mori-design-2.stl" scale="1.00 1.00 1.00"/>
      </geometry>
    </collision>
    <inertial>
      <mass value="0.100"/>
      <inertia ixx="6.25e-05" ixy="0.0" ixz="0.0" iyy="0.00025" iyz="0.0" izz="0.00019"/> <!--w=0.15, d=0.086, h=0.01, m=0.1-->
    </inertial>
  </link>

  <joint name="base_link_b_joint" type="revolute">
    <parent link="base_link"/>
    <child link="base_link_b"/>
    <axis xyz="0 1 0"/>
    <origin rpy="0 0 -2.0944" xyz="139 230 0"/>
    <limit effort="40" lower="-3.14" upper="3.14" velocity="0.1"/>
  </joint>

  <!-- wheel1 -->
  <link name="wheel1_b">
    <visual>
      <origin rpy="0.0 0 0" xyz="-8 0 -8"/>
      <geometry>
        <mesh filename="wheel.stl" scale="1.00 1.00 1.00"/>
      </geometry>
      <material name="blue"/>
    </visual>
    <collision>
      <origin rpy="0.0 0 0" xyz="-8 0 -8"/>
      <geometry>
        <mesh filename="wheel.stl" scale="1.00 1.00 1.00"/>
      </geometry>
    </collision>
  </link>

  <joint name="joint1_b" type="revolute">
    <parent link="base_link_b"/>
    <child link="wheel1_b"/>
    <axis xyz="0 1 0"/>
    <origin rpy="0 0 0" xyz="5 103 8"/>
    <limit effort="40" lower="-3.14" upper="3.14" velocity="0.1"/>
  </joint>

  <!-- wheel2 -->
  <link name="wheel2_b">
    <visual>
      <origin rpy="0.0 0 0" xyz="-8 0 -8"/>
      <geometry>
        <mesh filename="wheel.stl" scale="1.00 1.00 1.00"/>
      </geometry>
      <material name="blue"/>
    </visual>
    <collision>
      <origin rpy="0.0 0 0" xyz="-8 0 -8"/>
      <geometry>
        <mesh filename="wheel.stl" scale="1.00 1.00 1.00"/>
      </geometry>
    </collision>
  </link>

  <joint name="joint2_b" type="revolute">
    <parent link="base_link_b"/>
    <child link="wheel2_b"/>
    <axis xyz="0 1 0"/>
    <origin rpy="0 0 0" xyz="135 118 8"/>
    <limit effort="40" lower="-3.14" upper="3.14" velocity="0.1"/>
  </joint>

  <!-- wheel3 -->
  <link name="wheel3_b">
    <visual>
      <origin rpy="0.0 0 0" xyz="-8 0 -8"/>
      <geometry>
        <mesh filename="wheel.stl" scale="1.00 1.00 1.00"/>
      </geometry>
      <material name="blue"/>
    </visual>
    <collision>
      <origin rpy="0.0 0 0" xyz="-8 0 -8"/>
      <geometry>
        <mesh filename="wheel.stl" scale="1.00 1.00 1.00"/>
      </geometry>
    </collision>
  </link>

  <joint name="joint3_b" type="revolute">
    <parent link="base_link_b"/>
    <child link="wheel3_b"/>
    <axis xyz="0 1 0"/>
    <origin rpy="0 0 2.0944" xyz="46 25 8"/>
    <limit effort="40" lower="-3.14" upper="3.14" velocity="0.1"/>
  </joint>

  <!-- wheel4 -->
  <link name="wheel4_b">
    <visual>
      <origin rpy="0.0 0 0" xyz="-8 0 -8"/>
      <geometry>
        <mesh filename="wheel.stl" scale="1.00 1.00 1.00"/>
      </geometry>
      <material name="blue"/>
    </visual>
    <collision>
      <origin rpy="0.0 0 0" xyz="-8 0 -8"/>
      <geometry>
        <mesh filename="wheel.stl" scale="1.00 1.00 1.00"/>
      </geometry>
    </collision>
  </link>

  <joint name="joint4_b" type="revolute">
    <parent link="base_link_b"/>
    <child link="wheel4_b"/>
    <axis xyz="0 1 0"/>
    <origin rpy="0 0 2.0944" xyz="99 202 8"/>
    <limit effort="40" lower="-3.14" upper="3.14" velocity="0.1"/>
  </joint>

  <!-- base_link -->
  <link name="base_link_c">
    <visual>
      <origin rpy="0.0 0 0" xyz="0 0 0"/>
      <geometry>
        <mesh filename="mori-design-2.stl" scale="1.00 1.00 1.00"/>
      </geometry>
    </visual>
    <collision>
      <origin rpy="0.0 0 0" xyz="0 0 0"/>
      <geometry>
        <mesh filename="mori-design-2.stl" scale="1.00 1.00 1.00"/>
      </geometry>
    </collision>
    <inertial>
      <mass value="0.100"/>
      <inertia ixx="6.25e-05" ixy="0.0" ixz="0.0" iyy="0.00025" iyz="0.0" izz="0.00019"/> <!--w=0.15, d=0.086, h=0.01, m=0.1-->
    </inertial>
  </link>

  <joint name="base_link_c_joint" type="revolute">
    <parent link="base_link"/>
    <child link="base_link_c"/>
    <axis xyz="0 1 0"/>
    <origin rpy="0 0 0" xyz="0 -150 0"/>
    <limit effort="40" lower="-3.14" upper="3.14" velocity="0.1"/>
  </joint>

  <!-- wheel1 -->
  <link name="wheel1_c">
    <visual>
      <origin rpy="0.0 0 0" xyz="-8 0 -8"/>
      <geometry>
        <mesh filename="wheel.stl" scale="1.00 1.00 1.00"/>
      </geometry>
      <material name="blue"/>
    </visual>
    <collision>
      <origin rpy="0.0 0 0" xyz="-8 0 -8"/>
      <geometry>
        <mesh filename="wheel.stl" scale="1.00 1.00 1.00"/>
      </geometry>
    </collision>
  </link>

  <joint name="joint1_c" type="revolute">
    <parent link="base_link_c"/>
    <child link="wheel1_c"/>
    <axis xyz="0 1 0"/>
    <origin rpy="0 0 0" xyz="5 103 8"/>
    <limit effort="40" lower="-3.14" upper="3.14" velocity="0.1"/>
  </joint>

  <!-- wheel2 -->
  <link name="wheel2_c">
    <visual>
      <origin rpy="0.0 0 0" xyz="-8 0 -8"/>
      <geometry>
        <mesh filename="wheel.stl" scale="1.00 1.00 1.00"/>
      </geometry>
      <material name="blue"/>
    </visual>
    <collision>
      <origin rpy="0.0 0 0" xyz="-8 0 -8"/>
      <geometry>
        <mesh filename="wheel.stl" scale="1.00 1.00 1.00"/>
      </geometry>
    </collision>
  </link>

  <joint name="joint2_c" type="revolute">
    <parent link="base_link_c"/>
    <child link="wheel2_c"/>
    <axis xyz="0 1 0"/>
    <origin rpy="0 0 0" xyz="135 118 8"/>
    <limit effort="40" lower="-3.14" upper="3.14" velocity="0.1"/>
  </joint>

  <!-- wheel3 -->
  <link name="wheel3_c">
    <visual>
      <origin rpy="0.0 0 0" xyz="-8 0 -8"/>
      <geometry>
        <mesh filename="wheel.stl" scale="1.00 1.00 1.00"/>
      </geometry>
      <material name="blue"/>
    </visual>
    <collision>
      <origin rpy="0.0 0 0" xyz="-8 0 -8"/>
      <geometry>
        <mesh filename="wheel.stl" scale="1.00 1.00 1.00"/>
      </geometry>
    </collision>
  </link>

  <joint name="joint3_c" type="revolute">
    <parent link="base_link_c"/>
    <child link="wheel3_c"/>
    <axis xyz="0 1 0"/>
    <origin rpy="0 0 2.0944" xyz="46 25 8"/>
    <limit effort="40" lower="-3.14" upper="3.14" velocity="0.1"/>
  </joint>

  <!-- wheel4 -->
  <link name="wheel4_c">
    <visual>
      <origin rpy="0.0 0 0" xyz="-8 0 -8"/>
      <geometry>
        <mesh filename="wheel.stl" scale="1.00 1.00 1.00"/>
      </geometry>
      <material name="blue"/>
    </visual>
    <collision>
      <origin rpy="0.0 0 0" xyz="-8 0 -8"/>
      <geometry>
        <mesh filename="wheel.stl" scale="1.00 1.00 1.00"/>
      </geometry>
    </collision>
  </link>

  <joint name="joint4_c" type="revolute">
    <parent link="base_link_c"/>
    <child link="wheel4_c"/>
    <axis xyz="0 1 0"/>
    <origin rpy="0 0 2.0944" xyz="99 202 8"/>
    <limit effort="40" lower="-3.14" upper="3.14" velocity="0.1"/>
  </joint>

  <!-- base_link -->
  <link name="base_link_d">
    <visual>
      <origin rpy="0.0 0 0" xyz="0 0 0"/>
      <geometry>
        <mesh filename="mori-design-2.stl" scale="1.00 1.00 1.00"/>
      </geometry>
    </visual>
    <collision>
      <origin rpy="0.0 0 0" xyz="0 0 0"/>
      <geometry>
        <mesh filename="mori-design-2.stl" scale="1.00 1.00 1.00"/>
      </geometry>
    </collision>
    <inertial>
      <mass value="0.100"/>
      <inertia ixx="6.25e-05" ixy="0.0" ixz="0.0" iyy="0.00025" iyz="0.0" izz="0.00019"/> <!--w=0.15, d=0.086, h=0.01, m=0.1-->
    </inertial>
  </link>

  <joint name="base_link_d_joint" type="revolute">
    <parent link="base_link_c"/>
    <child link="base_link_d"/>
    <axis xyz="0 1 0"/>
    <origin rpy="0 0 -2.0944" xyz="139 230 0"/>
    <limit effort="40" lower="-3.14" upper="3.14" velocity="0.1"/>
  </joint>

  <!-- wheel1 -->
  <link name="wheel1_d">
    <visual>
      <origin rpy="0.0 0 0" xyz="-8 0 -8"/>
      <geometry>
        <mesh filename="wheel.stl" scale="1.00 1.00 1.00"/>
      </geometry>
      <material name="blue"/>
    </visual>
    <collision>
      <origin rpy="0.0 0 0" xyz="-8 0 -8"/>
      <geometry>
        <mesh filename="wheel.stl" scale="1.00 1.00 1.00"/>
      </geometry>
    </collision>
  </link>

  <joint name="joint1_d" type="revolute">
    <parent link="base_link_d"/>
    <child link="wheel1_d"/>
    <axis xyz="0 1 0"/>
    <origin rpy="0 0 0" xyz="5 103 8"/>
    <limit effort="40" lower="-3.14" upper="3.14" velocity="0.1"/>
  </joint>

  <!-- wheel2 -->
  <link name="wheel2_d">
    <visual>
      <origin rpy="0.0 0 0" xyz="-8 0 -8"/>
      <geometry>
        <mesh filename="wheel.stl" scale="1.00 1.00 1.00"/>
      </geometry>
      <material name="blue"/>
    </visual>
    <collision>
      <origin rpy="0.0 0 0" xyz="-8 0 -8"/>
      <geometry>
        <mesh filename="wheel.stl" scale="1.00 1.00 1.00"/>
      </geometry>
    </collision>
  </link>

  <joint name="joint2_d" type="revolute">
    <parent link="base_link_d"/>
    <child link="wheel2_d"/>
    <axis xyz="0 1 0"/>
    <origin rpy="0 0 0" xyz="135 118 8"/>
    <limit effort="40" lower="-3.14" upper="3.14" velocity="0.1"/>
  </joint>

  <!-- wheel3 -->
  <link name="wheel3_d">
    <visual>
      <origin rpy="0.0 0 0" xyz="-8 0 -8"/>
      <geometry>
        <mesh filename="wheel.stl" scale="1.00 1.00 1.00"/>
      </geometry>
      <material name="blue"/>
    </visual>
    <collision>
      <origin rpy="0.0 0 0" xyz="-8 0 -8"/>
      <geometry>
        <mesh filename="wheel.stl" scale="1.00 1.00 1.00"/>
      </geometry>
    </collision>
  </link>

  <joint name="joint3_d" type="revolute">
    <parent link="base_link_d"/>
    <child link="wheel3_d"/>
    <axis xyz="0 1 0"/>
    <origin rpy="0 0 2.0944" xyz="46 25 8"/>
    <limit effort="40" lower="-3.14" upper="3.14" velocity="0.1"/>
  </joint>

  <!-- wheel4 -->
  <link name="wheel4_d">
    <visual>
      <origin rpy="0.0 0 0" xyz="-8 0 -8"/>
      <geometry>
        <mesh filename="wheel.stl" scale="1.00 1.00 1.00"/>
      </geometry>
      <material name="blue"/>
    </visual>
    <collision>
      <origin rpy="0.0 0 0" xyz="-8 0 -8"/>
      <geometry>
        <mesh filename="wheel.stl" scale="1.00 1.00 1.00"/>
      </geometry>
    </collision>
  </link>

  <joint name="joint4_d" type="revolute">
    <parent link="base_link_d"/>
    <child link="wheel4_d"/>
    <axis xyz="0 1 0"/>
    <origin rpy="0 0 2.0944" xyz="99 202 8"/>
    <limit effort="40" lower="-3.14" upper="3.14" velocity="0.1"/>
  </joint>

</robot>